<?xml version="1.0"?>
<robot name="mammoth">

  <!--
      ROBOT BASE
  -->

  <link name="base_link">
    <visual>
      <geometry>
        <box size="0.8 0.4 0.3"/>
      </geometry>
    </visual>
    <collision>
      <geometry>
        <box size="0.8 0.4 0.3"/>
      </geometry>
    </collision>
    <!--inertial>
      <mass value="45"/>
      <inertia
        ixx="2.7375"  ixy="0.0" ixz="0.0"
                      iyy="3.0" iyz="0.0"
                                izz="0.9375"/>
    </inertial-->
  </link>

  <!--
      BACK RIGHT WHEEL LINK AND JOINT
  -->

  <link name="wheel_br">
    <visual>
      <geometry>
        <cylinder length="0.075" radius="0.125"/>
      </geometry>
    </visual>
    <collision>
      <geometry>
        <cylinder length="0.075" radius="0.125"/>
      </geometry>
      <contact_coefficients mu="0.72" resitution="0"  k_p="0"  k_d="0" />
    </collision>
    <inertial>
      <mass value="1.1"/>
      <inertia
        ixx="0.0048125" ixy="0.0"       ixz="0.0"
                        iyy="0.0048125" iyz="0.0"
                                        izz="0.00859375"/>
    </inertial>
  </link>

  <joint name="base_to_wheel_br" type="continuous">
    <axis xyz="0 0 1"/>
    <origin rpy="1.57 -3.14159 0" xyz="0.3 0.2375 -0.1"/>
    <parent link="base_link"/>
    <child link="wheel_br"/>
  </joint>

  <!--
      BACK LEFT WHEEL LINK AND JOINT
  -->

  <link name="wheel_bl">
    <visual>
      <geometry>
        <cylinder length="0.075" radius="0.125"/>
      </geometry>
    </visual>
    <collision>
      <geometry>
        <cylinder length="0.075" radius="0.125"/>
      </geometry>
      <contact_coefficients mu="0.72" resitution="0"  k_p="0"  k_d="0" />
    </collision>
    <inertial>
      <mass value="1.1"/>
      <inertia
        ixx="0.0048125" ixy="0.0"       ixz="0.0"
                        iyy="0.0048125" iyz="0.0"
                                        izz="0.00859375"/>
    </inertial>

  </link>

  <joint name="base_to_wheel_bl" type="continuous">
    <axis xyz="0 0 1"/>
    <origin rpy="1.57 -3.14159 0" xyz="0.3 -0.2375 -0.1"/>
    <parent link="base_link"/>
    <child link="wheel_bl"/>
  </joint>


  <!--
      FRONT RIGHT WHEEL LINK AND JOINT
  -->

  <link name="wheel_fr">  
    <visual>
      <geometry>
        <cylinder length="0.075" radius="0.125"/>
      </geometry>
    </visual>
    <collision>
      <geometry>
        <cylinder length="0.075" radius="0.125"/>
      </geometry>
      <contact_coefficients mu="0.72" resitution="0"  k_p="0"  k_d="0" />
    </collision>
    <inertial>
      <mass value="1.1"/>
      <inertia
        ixx="0.0048125" ixy="0.0"       ixz="0.0"
                        iyy="0.0048125" iyz="0.0"
                                        izz="0.00859375"/>
    </inertial>
  </link>

  <joint name="base_to_wheel_fr" type="continuous">
    <axis xyz="0 0 1"/>
    <origin rpy="1.57 -3.14159 0" xyz="-0.3 0.2375 -0.1"/>
    <parent link="base_link"/>
    <child link="wheel_fr"/>
  </joint>

  <!--
      FRONT LEFT WHEEL LINK AND JOINT
  -->

  <link name="wheel_fl">
    <visual>
      <geometry>
        <cylinder length="0.075" radius="0.125"/>
      </geometry>
    </visual>
    <collision>
      <geometry>
        <cylinder length="0.075" radius="0.125"/>
      </geometry>
      <contact_coefficients mu="0.72" resitution="0"  k_p="0"  k_d="0" />
    </collision>
    <inertial>
      <mass value="1.1"/>
      <inertia
        ixx="0.0048125" ixy="0.0"       ixz="0.0"
                        iyy="0.0048125" iyz="0.0"
                                        izz="0.00859375"/>
    </inertial>
  </link>



  <joint name="base_to_wheel_fl" type="continuous">
    <axis xyz="0 0 1"/>
    <origin rpy="1.57 -3.14159 0" xyz="-0.3 -0.2375 -0.1"/>
    <parent link="base_link"/>
    <child link="wheel_fl"/>
  </joint>


  <!--
      LIDAR LINK AND JOINT
  -->

  <link name="laser_link">
    <visual>
      <geometry>
        <cylinder length="0.05" radius="0.025"/>
      </geometry>
    </visual>
    <collision>
      <geometry>
        <cylinder length="0.05" radius="0.025"/>
      </geometry>
    </collision>
    <inertial>
      <mass value="1e-5" />
      <inertia ixx="1e-6" ixy="0" ixz="0" iyy="1e-6" iyz="0" izz="1e-6" />
    </inertial>

    <gazebo>
      <sensor type="gpu_lidar" name="laser_link">
        <update_rate>10</update_rate>
        <lidar>
          <scan>
            <horizontal>
              <samples>640</samples>
              <resolution>1</resolution>
              <min_angle>-1.396263</min_angle>
              <max_angle>1.396263</max_angle>
            </horizontal>
            <vertical>
              <samples>16</samples>
              <resolution>1</resolution>
              <min_angle>-0.261799</min_angle>
              <max_angle>0.261799</max_angle>
            </vertical>
          </scan>
          <range>
            <min>0.08</min>
            <max>10.0</max>
            <resolution>0.01</resolution>
          </range>
        </lidar>
        <alwaysOn>1</alwaysOn>
        <visualize>true</visualize>
      </sensor>
    </gazebo>
  </link>

  <joint name="base_to_laser" type="fixed">
    <origin rpy="0 0 0" xyz="0 0 0.175"/>
    <parent link="base_link"/>
    <child link="laser_link"/>
  </joint>

  <!--
      Todo: add world tags for plugins...
      GAZEBO MOTION
  -->
  <gazebo>
    <plugin filename="libignition-gazebo-diff-drive-system.so" name="ignition::gazebo::systems::DiffDrive">
      <left_joint>base_to_wheel_bl</left_joint>
      <right_joint>base_to_wheel_br</right_joint>
      <left_joint>base_to_wheel_fl</left_joint>
      <right_joint>base_to_wheel_fr</right_joint>
      <wheel_separation>0.475</wheel_separation>
      <wheel_radius>0.125</wheel_radius>
      <odom_publish_frequency>1</odom_publish_frequency>

      <frame_id>odom</frame_id>
      <child_frame_id>base_link</child_frame_id>
    </plugin>
  </gazebo>

</robot>
