<?xml version="1.0"?>
<robot name="mammoth">

  <!-- Robot Footprint -->
  <link name="base_footprint"/>
  
  <!--
      ROBOT BASE
  -->
  
  <link name="base_link">
    <visual>
      <geometry>
        <box size="0.8 0.4 0.3"/>
      </geometry>
    </visual>
    <collision>
      <geometry>
        <box size="0.8 0.4 0.3"/>
      </geometry>
    </collision>
  </link>
	
  <joint name="base_footprint_to_base_link" type="fixed">
    <origin rpy="0 0 3.14" xyz="0 0 0.225"/>
    <parent link="base_footprint"/>
    <child link="base_link"/>
  </joint>

  <!--	
      BACK LEFT WHEEL LINK AND JOINT
  -->

  <link name="wheel_bl">
    <visual>
      <geometry>
        <cylinder length="0.075" radius="0.125"/>
      </geometry>
    </visual>
    <collision>
      <geometry>
        <cylinder length="0.075" radius="0.125"/>
      </geometry>
      <contact_coefficients mu="0.72" resitution="0"  k_p="0"  k_d="0" />
    </collision>
    <inertial>
      <mass value="1.1"/>
      <inertia
        ixx="0.0048125" ixy="0.0"       ixz="0.0"
                        iyy="0.0048125" iyz="0.0"
                                        izz="0.00859375"/>
    </inertial>

  </link>

  <joint name="base_to_wheel_bl" type="continuous">
    <axis xyz="0 0 1"/>
    <origin rpy="1.57 -3.14159 0" xyz="0.3 -0.2375 -0.1"/>
    <parent link="base_link"/>
    <child link="wheel_bl"/>
  </joint>

  <!--
      POSTERIOR LEFT WHEEL LINK AND JOINT
  -->

  <link name="wheel_pl">
    <visual>
      <geometry>
        <cylinder length="0.075" radius="0.125"/>
      </geometry>
    </visual>
    <collision>
      <geometry>
        <cylinder length="0.075" radius="0.125"/>
      </geometry>
      <contact_coefficients mu="0.72" resitution="0"  k_p="0"  k_d="0" />
    </collision>
    <inertial>
      <mass value="1.1"/>
      <inertia
        ixx="0.0048125" ixy="0.0"       ixz="0.0"
                        iyy="0.0048125" iyz="0.0"
                                        izz="0.00859375"/>
    </inertial>
  </link>

  <joint name="base_to_wheel_pl" type="continuous">
    <axis xyz="0 0 1"/>
    <origin rpy="1.57 -3.14159 0" xyz="-0.15 -0.2375 -0.1"/>    
    <parent link="base_link"/>
    <child link="wheel_pl"/>
  </joint>

  <!--
      MIDDLE LEFT WHEEL LINK AND JOINT
  -->

  <link name="wheel_ml">
    <visual>
      <geometry>
        <cylinder length="0.075" radius="0.125"/>
      </geometry>
    </visual>
    <collision>
      <geometry>
        <cylinder length="0.075" radius="0.125"/>
      </geometry>
      <contact_coefficients mu="0.72" resitution="0"  k_p="0"  k_d="0" />
    </collision>
    <inertial>
      <mass value="1.1"/>
      <inertia
        ixx="0.0048125" ixy="0.0"       ixz="0.0"
                        iyy="0.0048125" iyz="0.0"
                                        izz="0.00859375"/>
    </inertial>
  </link>

  <joint name="base_to_wheel_ml" type="continuous">
    <axis xyz="0 0 1"/>
    <origin rpy="1.57 -3.14159 0" xyz="0 -0.2375 -0.1"/>
    <parent link="base_link"/>
    <child link="wheel_ml"/>
  </joint>

  <!--
      ANTERIOR LEFT WHEEL LINK AND JOINT
  -->

  <link name="wheel_al">
    <visual>
      <geometry>
        <cylinder length="0.075" radius="0.125"/>
      </geometry>
    </visual>
    <collision>
      <geometry>
        <cylinder length="0.075" radius="0.125"/>
      </geometry>
      <contact_coefficients mu="0.72" resitution="0"  k_p="0"  k_d="0" />
    </collision>
    <inertial>
      <mass value="1.1"/>
      <inertia
        ixx="0.0048125" ixy="0.0"       ixz="0.0"
                        iyy="0.0048125" iyz="0.0"
                                        izz="0.00859375"/>
    </inertial>
  </link>

  <joint name="base_to_wheel_al" type="continuous">
    <axis xyz="0 0 1"/>
    <origin rpy="1.57 -3.14159 0" xyz="0.15 -0.2375 -0.1"/>
    <parent link="base_link"/>
    <child link="wheel_al"/>
  </joint>


  <!--
      FRONT LEFT WHEEL LINK AND JOINT
  -->

  <link name="wheel_fl">
    <visual>
      <geometry>
        <cylinder length="0.075" radius="0.125"/>
      </geometry>
    </visual>
    <collision>
      <geometry>
        <cylinder length="0.075" radius="0.125"/>
      </geometry>
      <contact_coefficients mu="0.72" resitution="0"  k_p="0"  k_d="0" />
    </collision>
    <inertial>
      <mass value="1.1"/>
      <inertia
        ixx="0.0048125" ixy="0.0"       ixz="0.0"
                        iyy="0.0048125" iyz="0.0"
                                        izz="0.00859375"/>
    </inertial>
  </link>


  <joint name="base_to_wheel_fl" type="continuous">
    <axis xyz="0 0 1"/>
    <origin rpy="1.57 -3.14159 0" xyz="-0.3 -0.2375 -0.1"/>    
    <parent link="base_link"/>
    <child link="wheel_fl"/>
  </joint>

  <!--
      BACK RIGHT WHEEL LINK AND JOINT
  -->

  <link name="wheel_br">
    <origin rpy="1.57 -3.14159 0" xyz="0.3 0.2375 -0.1"/>
    <visual>
      <geometry>
        <cylinder length="0.075" radius="0.125"/>
      </geometry>
    </visual>
    <collision>
      <geometry>
        <cylinder length="0.075" radius="0.125"/>
      </geometry>
      <contact_coefficients mu="0.72" resitution="0"  k_p="0"  k_d="0" />
    </collision>
    <inertial>
      <mass value="1.1"/>
      <inertia
        ixx="0.0048125" ixy="0.0"       ixz="0.0"
                        iyy="0.0048125" iyz="0.0"
                                        izz="0.00859375"/>
    </inertial>
  </link>

  <joint name="base_to_wheel_br" type="continuous">
    <axis xyz="0 0 1"/>
    <origin rpy="1.57 -3.14159 0" xyz="0.3 0.2375 -0.1"/>
    <parent link="base_link"/>
    <child link="wheel_br"/>
  </joint>

  <!--
      POSTERIOR RIGHT WHEEL LINK AND JOINT
  -->

  <link name="wheel_pr">
    <visual>
      <geometry>
        <cylinder length="0.075" radius="0.125"/>
      </geometry>
    </visual>
    <collision>
      <geometry>
        <cylinder length="0.075" radius="0.125"/>
      </geometry>
      <contact_coefficients mu="0.72" resitution="0"  k_p="0"  k_d="0" />
    </collision>
    <inertial>
      <mass value="1.1"/>
      <inertia
        ixx="0.0048125" ixy="0.0"       ixz="0.0"
                        iyy="0.0048125" iyz="0.0"
                                        izz="0.00859375"/>
    </inertial>
  </link>

  <joint name="base_to_wheel_pr" type="continuous">
    <axis xyz="0 0 1"/>
    <origin rpy="1.57 -3.14159 0" xyz="-0.15 0.2375 -0.1"/>
    <parent link="base_link"/>
    <child link="wheel_pr"/>
  </joint>

  <!--
      MIDDLE RIGHT WHEEL LINK AND JOINT
  -->

  <link name="wheel_mr">
    <visual>
      <geometry>
        <cylinder length="0.075" radius="0.125"/>
      </geometry>
    </visual>
    <collision>
      <geometry>
        <cylinder length="0.075" radius="0.125"/>
      </geometry>
      <contact_coefficients mu="0.72" resitution="0"  k_p="0"  k_d="0" />
    </collision>
    <inertial>
      <mass value="1.1"/>
      <inertia
        ixx="0.0048125" ixy="0.0"       ixz="0.0"
                        iyy="0.0048125" iyz="0.0"
                                        izz="0.00859375"/>
    </inertial>

  </link>

  <joint name="base_to_wheel_mr" type="continuous">
    <axis xyz="0 0 1"/>
    <origin rpy="1.57 -3.14159 0" xyz="0 0.2375 -0.1"/>
    <parent link="base_link"/>
    <child link="wheel_mr"/>
  </joint>


  <!--
      ANTERIOR RIGHT WHEEL LINK AND JOINT
  -->

  <link name="wheel_ar">
    <visual>
      <geometry>
        <cylinder length="0.075" radius="0.125"/>
      </geometry>
    </visual>
    <collision>
      <geometry>
        <cylinder length="0.075" radius="0.125"/>
      </geometry>
      <contact_coefficients mu="0.72" resitution="0"  k_p="0"  k_d="0" />
    </collision>
    <inertial>
      <mass value="1.1"/>
      <inertia
        ixx="0.0048125" ixy="0.0"       ixz="0.0"
                        iyy="0.0048125" iyz="0.0"
                                        izz="0.00859375"/>
    </inertial>
  </link>

  <joint name="base_to_wheel_ar" type="continuous">
    <axis xyz="0 0 1"/>
    <origin rpy="1.57 -3.14159 0" xyz="0.15 0.2375 -0.1"/>
    <parent link="base_link"/>
    <child link="wheel_ar"/>
  </joint>


  <!--
      FRONT RIGHT WHEEL LINK AND JOINT
  -->

  <link name="wheel_fr">  
    <visual>
      <geometry>
        <cylinder length="0.075" radius="0.125"/>
      </geometry>
    </visual>
    <collision>
      <geometry>
        <cylinder length="0.075" radius="0.125"/>
      </geometry>
      <contact_coefficients mu="0.72" resitution="0"  k_p="0"  k_d="0" />
    </collision>
    <inertial>
      <mass value="1.1"/>
      <inertia
        ixx="0.0048125" ixy="0.0"       ixz="0.0"
                        iyy="0.0048125" iyz="0.0"
                                        izz="0.00859375"/>
    </inertial>
  </link>

  <joint name="base_to_wheel_fr" type="continuous">
    <axis xyz="0 0 1"/>
    <origin rpy="1.57 -3.14159 0" xyz="-0.3 0.2375 -0.1"/>
    <parent link="base_link"/>
    <child link="wheel_fr"/>
  </joint>

  <!--
      LIDAR LINK, IMU LINK AND JOINT
  -->

  <link name="laser_link">
    <origin rpy="0 0 3.14" xyz="-0.3048 0 0.175"/>
    <visual>
      <geometry>
        <cylinder length="0.05" radius="0.025"/>
      </geometry>
    </visual>
    <collision>
      <geometry>
        <cylinder length="0.05" radius="0.025"/>
      </geometry>
    </collision>
    <inertial>
      <mass value="1e-5" />
      <inertia ixx="1e-6" ixy="0" ixz="0" iyy="1e-6" iyz="0" izz="1e-6" />
    </inertial>
  </link>

  <joint name="base_to_laser" type="fixed">
    <origin rpy="0 0 3.14" xyz="-0.3048 0 0.175"/>
    <parent link="base_link"/>
    <child link="laser_link"/>
  </joint>


 <link name="imu_link">
    <origin rpy="0 0 3.14" xyz="-0.3048 0 0.175"/>
    <visual>
      <geometry>
        <cylinder length="0.05" radius="0.025"/>
      </geometry>
    </visual>
    <collision>
      <geometry>
        <cylinder length="0.05" radius="0.025"/>
      </geometry>
    </collision>
    <inertial>
      <mass value="1e-5" />
      <inertia ixx="1e-6" ixy="0" ixz="0" iyy="1e-6" iyz="0" izz="1e-6" />
    </inertial>
  </link>

  <joint name="base_to_imu" type="fixed">
    <origin rpy="0 0 3.14" xyz="-0.3048 0 0.175"/>
    <parent link="base_link"/>
    <child link="imu_link"/>
  </joint>
</robot>
