<?xml version="1.0"?>
<robot name="mammoth">

  <!--
      ROBOT BASE
  -->

  <link name="base_link">
    <visual>
      <geometry>
        <box size="0.8 0.4 0.3"/>
      </geometry>
    </visual>
    <collision>
      <geometry>
        <box size="0.8 0.4 0.3"/>
      </geometry>
    </collision>
    <!--inertial>
      <mass value="45"/>
      <inertia
        ixx="2.7375"  ixy="0.0" ixz="0.0"
                      iyy="3.0" iyz="0.0"
                                izz="0.9375"/>
    </inertial-->
  </link>

<!--
    BACK RIGHT WHEEL LINK AND JOINT
-->

  <link name="wheel_br">
    <visual>
      <geometry>
        <cylinder length="0.075" radius="0.125"/>
      </geometry>
    </visual>
    <collision>
      <geometry>
        <cylinder length="0.075" radius="0.125"/>
      </geometry>
    </collision>
    <inertial>
      <mass value="1.1"/>
      <inertia
        ixx="0.0048125" ixy="0.0"       ixz="0.0"
                        iyy="0.0048125" iyz="0.0"
                                        izz="0.00859375"/>
    </inertial>
  </link>

  <joint name="base_to_wheel_br" type="continuous">
    <axis xyz="0 0 1"/>
    <origin rpy="1.57 -3.14159 0" xyz="0.3 0.2375 -0.1"/>
    <parent link="base_link"/>
    <child link="wheel_br"/>
  </joint>

  <!--
      BACK LEFT WHEEL LINK AND JOINT
  -->

  <link name="wheel_bl">
    <visual>
      <geometry>
        <cylinder length="0.075" radius="0.125"/>
      </geometry>
    </visual>
    <collision>
      <geometry>
        <cylinder length="0.075" radius="0.125"/>
      </geometry>
    </collision>
    <inertial>
      <mass value="1.1"/>
      <inertia
        ixx="0.0048125" ixy="0.0"       ixz="0.0"
                        iyy="0.0048125" iyz="0.0"
                                        izz="0.00859375"/>
    </inertial>
  </link>

  <joint name="base_to_wheel_bl" type="continuous">
    <axis xyz="0 0 1"/>
    <origin rpy="1.57 -3.14159 0" xyz="0.3 -0.2375 -0.1"/>
    <parent link="base_link"/>
    <child link="wheel_bl"/>
  </joint>

  <!--
      FRONT CASTER LINK AND JOINT
  -->

  <link name="caster_front">
    <visual>
      <geometry>
        <sphere radius="0.125"/>
      </geometry>
    </visual>
    <collision>
      <geometry>
        <sphere radius="0.125"/>
      </geometry>
    </collision>
    <inertial>
      <mass value="2.2"/>
      <inertia
        ixx="0.01375" ixy="0.0"     ixz="0.0"
                      iyy="0.01375" iyz="0.0"
                                    izz="0.01375"/>
    </inertial>
  </link>

  <joint name="base_to_caster_front" type="fixed">
    <origin rpy="0 0 0" xyz="-0.25 0 -0.1"/>
    <parent link="base_link"/>
    <child link="caster_front"/>
  </joint>

  <!--
      LIDAR LINK AND JOINT
  -->

  <link name="laser_link">
    <visual>
      <geometry>
        <cylinder length="0.05" radius="0.025"/>
      </geometry>
    </visual>
    <collision>
      <geometry>
        <cylinder length="0.05" radius="0.025"/>
      </geometry>
    </collision>
    <inertial>
      <mass value="1e-5" />
      <inertia ixx="1e-6" ixy="0" ixz="0" iyy="1e-6" iyz="0" izz="1e-6" />
    </inertial>
  </link>

  <joint name="base_to_laser" type="fixed">
    <origin rpy="0 0 0" xyz="0 0 0.175"/>
    <parent link="base_link"/>
    <child link="laser_link"/>
  </joint>

  <gazebo reference="laser_link">
    <sensor type="ray" name="laser_sensor">
      <always_on>true</always_on>
      <visualize>true</visualize>
      <update_rate>30</update_rate>
      <ray>
        <scan>
          <horizontal>
            <samples>10</samples>
            <resolution>1</resolution>
            <min_angle>-0.523</min_angle>
            <max_angle>0.523</max_angle>
          </horizontal>
          <vertical>
            <samples>10</samples>
            <resolution>1</resolution>
            <min_angle>-0.523</min_angle>
            <max_angle>0.523</max_angle>
          </vertical>
        </scan>
        <range>
          <min>0.10</min>
          <max>5.0</max>
          <resolution>0.01</resolution>
        </range>
      </ray>
      <noise>
        <type>gaussian</type>
        <mean>0.0</mean>
        <stddev>0.01</stddev>
      </noise>

      <plugin name="gazebo_ros_block_laser_controller" filename="libgazebo_ros_ray_sensor.so">
        <!-- Change namespace and output topic so published topic is /rrbot/laser/pointcloud -->
        <ros>
          <namespace>/gazebo</namespace>
          <argument>~/out:=pointcloud</argument>
        </ros>
        <!-- Set output to sensor_msgs/PointCloud to get same output type as gazebo_ros_block_laser -->
        <output_type>sensor_msgs/PointCloud2</output_type>
        <frame_name>laser_link</frame_name>
        <min_intensity>100.0</min_intensity>
      </plugin>
    </sensor>
  </gazebo>

  <!--
      GAZEBO MOTION
  -->
  <gazebo>
    <plugin name="diff_drive" filename="libgazebo_ros_diff_drive.so">

      <ros>
        <!-- gazebo namespace -->
        <namespace>/gazebo</namespace>

        <!-- Remapping gazebo topics
        <argument>cmd_vel:=new_cmd_vel</argument>
        <argument>odom:=new_odom</argument>
        -->
      </ros>

      <update_rate>100</update_rate>

      <!-- wheel joints -->
      <left_joint>base_to_wheel_bl</left_joint>
      <right_joint>base_to_wheel_br</right_joint>

      <!-- kinematics -->
      <wheel_separation>0.475</wheel_separation>
      <wheel_diameter>0.25</wheel_diameter>
      <max_acceleration>1.0</max_acceleration>
      <max_wheel_torque>20</max_wheel_torque>

      <!-- tf -->
      <odometry_frame>odom</odometry_frame>
      <robot_base_frame>base_link</robot_base_frame>

      <!-- output -->
      <publish_odom>true</publish_odom>
      <publish_odom_tf>true</publish_odom_tf>
      <publish_wheel_tf>false</publish_wheel_tf>
    </plugin>
  </gazebo>

</robot>
